Watching for file changes with StatReloader
Exception in thread django-main-thread:
Traceback (most recent call last):
  File "/root/RMS/Server/lvenv/lib/python3.8/site-packages/django/db/backends/base/base.py", line 219, in ensure_connection
    self.connect()
  File "/root/RMS/Server/lvenv/lib/python3.8/site-packages/django/utils/asyncio.py", line 33, in inner
    return func(*args, **kwargs)
  File "/root/RMS/Server/lvenv/lib/python3.8/site-packages/django/db/backends/base/base.py", line 200, in connect
    self.connection = self.get_new_connection(conn_params)
  File "/root/RMS/Server/lvenv/lib/python3.8/site-packages/django/utils/asyncio.py", line 33, in inner
    return func(*args, **kwargs)
  File "/root/RMS/Server/lvenv/lib/python3.8/site-packages/django/db/backends/postgresql/base.py", line 187, in get_new_connection
    connection = Database.connect(**conn_params)
  File "/root/RMS/Server/lvenv/lib/python3.8/site-packages/psycopg2/__init__.py", line 122, in connect
    conn = _connect(dsn, connection_factory=connection_factory, **kwasync)
psycopg2.OperationalError: FATAL:  password authentication failed for user "postgres"
FATAL:  password authentication failed for user "postgres"


The above exception was the direct cause of the following exception:

Traceback (most recent call last):
  File "/usr/lib/python3.8/threading.py", line 932, in _bootstrap_inner
    self.run()
  File "/usr/lib/python3.8/threading.py", line 870, in run
    self._target(*self._args, **self._kwargs)
  File "/root/RMS/Server/lvenv/lib/python3.8/site-packages/django/utils/autoreload.py", line 64, in wrapper
    fn(*args, **kwargs)
  File "/root/RMS/Server/lvenv/lib/python3.8/site-packages/django/core/management/commands/runserver.py", line 121, in inner_run
    self.check_migrations()
  File "/root/RMS/Server/lvenv/lib/python3.8/site-packages/django/core/management/base.py", line 486, in check_migrations
    executor = MigrationExecutor(connections[DEFAULT_DB_ALIAS])
  File "/root/RMS/Server/lvenv/lib/python3.8/site-packages/django/db/migrations/executor.py", line 18, in __init__
    self.loader = MigrationLoader(self.connection)
  File "/root/RMS/Server/lvenv/lib/python3.8/site-packages/django/db/migrations/loader.py", line 53, in __init__
    self.build_graph()
  File "/root/RMS/Server/lvenv/lib/python3.8/site-packages/django/db/migrations/loader.py", line 220, in build_graph
    self.applied_migrations = recorder.applied_migrations()
  File "/root/RMS/Server/lvenv/lib/python3.8/site-packages/django/db/migrations/recorder.py", line 77, in applied_migrations
    if self.has_table():
  File "/root/RMS/Server/lvenv/lib/python3.8/site-packages/django/db/migrations/recorder.py", line 55, in has_table
    with self.connection.cursor() as cursor:
  File "/root/RMS/Server/lvenv/lib/python3.8/site-packages/django/utils/asyncio.py", line 33, in inner
    return func(*args, **kwargs)
  File "/root/RMS/Server/lvenv/lib/python3.8/site-packages/django/db/backends/base/base.py", line 259, in cursor
    return self._cursor()
  File "/root/RMS/Server/lvenv/lib/python3.8/site-packages/django/db/backends/base/base.py", line 235, in _cursor
    self.ensure_connection()
  File "/root/RMS/Server/lvenv/lib/python3.8/site-packages/django/utils/asyncio.py", line 33, in inner
    return func(*args, **kwargs)
  File "/root/RMS/Server/lvenv/lib/python3.8/site-packages/django/db/backends/base/base.py", line 219, in ensure_connection
    self.connect()
  File "/root/RMS/Server/lvenv/lib/python3.8/site-packages/django/db/utils.py", line 90, in __exit__
    raise dj_exc_value.with_traceback(traceback) from exc_value
  File "/root/RMS/Server/lvenv/lib/python3.8/site-packages/django/db/backends/base/base.py", line 219, in ensure_connection
    self.connect()
  File "/root/RMS/Server/lvenv/lib/python3.8/site-packages/django/utils/asyncio.py", line 33, in inner
    return func(*args, **kwargs)
  File "/root/RMS/Server/lvenv/lib/python3.8/site-packages/django/db/backends/base/base.py", line 200, in connect
    self.connection = self.get_new_connection(conn_params)
  File "/root/RMS/Server/lvenv/lib/python3.8/site-packages/django/utils/asyncio.py", line 33, in inner
    return func(*args, **kwargs)
  File "/root/RMS/Server/lvenv/lib/python3.8/site-packages/django/db/backends/postgresql/base.py", line 187, in get_new_connection
    connection = Database.connect(**conn_params)
  File "/root/RMS/Server/lvenv/lib/python3.8/site-packages/psycopg2/__init__.py", line 122, in connect
    conn = _connect(dsn, connection_factory=connection_factory, **kwasync)
django.db.utils.OperationalError: FATAL:  password authentication failed for user "postgres"
FATAL:  password authentication failed for user "postgres"

Watching for file changes with StatReloader
Exception in thread django-main-thread:
Traceback (most recent call last):
  File "/root/RMS/Server/lvenv/lib/python3.8/site-packages/django/db/backends/base/base.py", line 219, in ensure_connection
    self.connect()
  File "/root/RMS/Server/lvenv/lib/python3.8/site-packages/django/utils/asyncio.py", line 33, in inner
    return func(*args, **kwargs)
  File "/root/RMS/Server/lvenv/lib/python3.8/site-packages/django/db/backends/base/base.py", line 200, in connect
    self.connection = self.get_new_connection(conn_params)
  File "/root/RMS/Server/lvenv/lib/python3.8/site-packages/django/utils/asyncio.py", line 33, in inner
    return func(*args, **kwargs)
  File "/root/RMS/Server/lvenv/lib/python3.8/site-packages/django/db/backends/postgresql/base.py", line 187, in get_new_connection
    connection = Database.connect(**conn_params)
  File "/root/RMS/Server/lvenv/lib/python3.8/site-packages/psycopg2/__init__.py", line 122, in connect
    conn = _connect(dsn, connection_factory=connection_factory, **kwasync)
psycopg2.OperationalError: FATAL:  password authentication failed for user "postgres"
FATAL:  password authentication failed for user "postgres"


The above exception was the direct cause of the following exception:

Traceback (most recent call last):
  File "/usr/lib/python3.8/threading.py", line 932, in _bootstrap_inner
    self.run()
  File "/usr/lib/python3.8/threading.py", line 870, in run
    self._target(*self._args, **self._kwargs)
  File "/root/RMS/Server/lvenv/lib/python3.8/site-packages/django/utils/autoreload.py", line 64, in wrapper
    fn(*args, **kwargs)
  File "/root/RMS/Server/lvenv/lib/python3.8/site-packages/django/core/management/commands/runserver.py", line 121, in inner_run
    self.check_migrations()
  File "/root/RMS/Server/lvenv/lib/python3.8/site-packages/django/core/management/base.py", line 486, in check_migrations
    executor = MigrationExecutor(connections[DEFAULT_DB_ALIAS])
  File "/root/RMS/Server/lvenv/lib/python3.8/site-packages/django/db/migrations/executor.py", line 18, in __init__
    self.loader = MigrationLoader(self.connection)
  File "/root/RMS/Server/lvenv/lib/python3.8/site-packages/django/db/migrations/loader.py", line 53, in __init__
    self.build_graph()
  File "/root/RMS/Server/lvenv/lib/python3.8/site-packages/django/db/migrations/loader.py", line 220, in build_graph
    self.applied_migrations = recorder.applied_migrations()
  File "/root/RMS/Server/lvenv/lib/python3.8/site-packages/django/db/migrations/recorder.py", line 77, in applied_migrations
    if self.has_table():
  File "/root/RMS/Server/lvenv/lib/python3.8/site-packages/django/db/migrations/recorder.py", line 55, in has_table
    with self.connection.cursor() as cursor:
  File "/root/RMS/Server/lvenv/lib/python3.8/site-packages/django/utils/asyncio.py", line 33, in inner
    return func(*args, **kwargs)
  File "/root/RMS/Server/lvenv/lib/python3.8/site-packages/django/db/backends/base/base.py", line 259, in cursor
    return self._cursor()
  File "/root/RMS/Server/lvenv/lib/python3.8/site-packages/django/db/backends/base/base.py", line 235, in _cursor
    self.ensure_connection()
  File "/root/RMS/Server/lvenv/lib/python3.8/site-packages/django/utils/asyncio.py", line 33, in inner
    return func(*args, **kwargs)
  File "/root/RMS/Server/lvenv/lib/python3.8/site-packages/django/db/backends/base/base.py", line 219, in ensure_connection
    self.connect()
  File "/root/RMS/Server/lvenv/lib/python3.8/site-packages/django/db/utils.py", line 90, in __exit__
    raise dj_exc_value.with_traceback(traceback) from exc_value
  File "/root/RMS/Server/lvenv/lib/python3.8/site-packages/django/db/backends/base/base.py", line 219, in ensure_connection
    self.connect()
  File "/root/RMS/Server/lvenv/lib/python3.8/site-packages/django/utils/asyncio.py", line 33, in inner
    return func(*args, **kwargs)
  File "/root/RMS/Server/lvenv/lib/python3.8/site-packages/django/db/backends/base/base.py", line 200, in connect
    self.connection = self.get_new_connection(conn_params)
  File "/root/RMS/Server/lvenv/lib/python3.8/site-packages/django/utils/asyncio.py", line 33, in inner
    return func(*args, **kwargs)
  File "/root/RMS/Server/lvenv/lib/python3.8/site-packages/django/db/backends/postgresql/base.py", line 187, in get_new_connection
    connection = Database.connect(**conn_params)
  File "/root/RMS/Server/lvenv/lib/python3.8/site-packages/psycopg2/__init__.py", line 122, in connect
    conn = _connect(dsn, connection_factory=connection_factory, **kwasync)
django.db.utils.OperationalError: FATAL:  password authentication failed for user "postgres"
FATAL:  password authentication failed for user "postgres"

Performing system checks...

System check identified no issues (0 silenced).
Watching for file changes with StatReloader
Exception in thread django-main-thread:
Traceback (most recent call last):
  File "/root/RMS/Server/lvenv/lib/python3.8/site-packages/django/db/backends/base/base.py", line 219, in ensure_connection
    self.connect()
  File "/root/RMS/Server/lvenv/lib/python3.8/site-packages/django/utils/asyncio.py", line 33, in inner
    return func(*args, **kwargs)
  File "/root/RMS/Server/lvenv/lib/python3.8/site-packages/django/db/backends/base/base.py", line 200, in connect
    self.connection = self.get_new_connection(conn_params)
  File "/root/RMS/Server/lvenv/lib/python3.8/site-packages/django/utils/asyncio.py", line 33, in inner
    return func(*args, **kwargs)
  File "/root/RMS/Server/lvenv/lib/python3.8/site-packages/django/db/backends/postgresql/base.py", line 187, in get_new_connection
    connection = Database.connect(**conn_params)
  File "/root/RMS/Server/lvenv/lib/python3.8/site-packages/psycopg2/__init__.py", line 122, in connect
    conn = _connect(dsn, connection_factory=connection_factory, **kwasync)
psycopg2.OperationalError: FATAL:  password authentication failed for user "postgres"
FATAL:  password authentication failed for user "postgres"


The above exception was the direct cause of the following exception:

Traceback (most recent call last):
  File "/usr/lib/python3.8/threading.py", line 932, in _bootstrap_inner
    self.run()
  File "/usr/lib/python3.8/threading.py", line 870, in run
    self._target(*self._args, **self._kwargs)
  File "/root/RMS/Server/lvenv/lib/python3.8/site-packages/django/utils/autoreload.py", line 64, in wrapper
    fn(*args, **kwargs)
  File "/root/RMS/Server/lvenv/lib/python3.8/site-packages/django/core/management/commands/runserver.py", line 121, in inner_run
    self.check_migrations()
  File "/root/RMS/Server/lvenv/lib/python3.8/site-packages/django/core/management/base.py", line 486, in check_migrations
    executor = MigrationExecutor(connections[DEFAULT_DB_ALIAS])
  File "/root/RMS/Server/lvenv/lib/python3.8/site-packages/django/db/migrations/executor.py", line 18, in __init__
    self.loader = MigrationLoader(self.connection)
  File "/root/RMS/Server/lvenv/lib/python3.8/site-packages/django/db/migrations/loader.py", line 53, in __init__
    self.build_graph()
  File "/root/RMS/Server/lvenv/lib/python3.8/site-packages/django/db/migrations/loader.py", line 220, in build_graph
    self.applied_migrations = recorder.applied_migrations()
  File "/root/RMS/Server/lvenv/lib/python3.8/site-packages/django/db/migrations/recorder.py", line 77, in applied_migrations
    if self.has_table():
  File "/root/RMS/Server/lvenv/lib/python3.8/site-packages/django/db/migrations/recorder.py", line 55, in has_table
    with self.connection.cursor() as cursor:
  File "/root/RMS/Server/lvenv/lib/python3.8/site-packages/django/utils/asyncio.py", line 33, in inner
    return func(*args, **kwargs)
  File "/root/RMS/Server/lvenv/lib/python3.8/site-packages/django/db/backends/base/base.py", line 259, in cursor
    return self._cursor()
  File "/root/RMS/Server/lvenv/lib/python3.8/site-packages/django/db/backends/base/base.py", line 235, in _cursor
    self.ensure_connection()
  File "/root/RMS/Server/lvenv/lib/python3.8/site-packages/django/utils/asyncio.py", line 33, in inner
    return func(*args, **kwargs)
  File "/root/RMS/Server/lvenv/lib/python3.8/site-packages/django/db/backends/base/base.py", line 219, in ensure_connection
    self.connect()
  File "/root/RMS/Server/lvenv/lib/python3.8/site-packages/django/db/utils.py", line 90, in __exit__
    raise dj_exc_value.with_traceback(traceback) from exc_value
  File "/root/RMS/Server/lvenv/lib/python3.8/site-packages/django/db/backends/base/base.py", line 219, in ensure_connection
    self.connect()
  File "/root/RMS/Server/lvenv/lib/python3.8/site-packages/django/utils/asyncio.py", line 33, in inner
    return func(*args, **kwargs)
  File "/root/RMS/Server/lvenv/lib/python3.8/site-packages/django/db/backends/base/base.py", line 200, in connect
    self.connection = self.get_new_connection(conn_params)
  File "/root/RMS/Server/lvenv/lib/python3.8/site-packages/django/utils/asyncio.py", line 33, in inner
    return func(*args, **kwargs)
  File "/root/RMS/Server/lvenv/lib/python3.8/site-packages/django/db/backends/postgresql/base.py", line 187, in get_new_connection
    connection = Database.connect(**conn_params)
  File "/root/RMS/Server/lvenv/lib/python3.8/site-packages/psycopg2/__init__.py", line 122, in connect
    conn = _connect(dsn, connection_factory=connection_factory, **kwasync)
django.db.utils.OperationalError: FATAL:  password authentication failed for user "postgres"
FATAL:  password authentication failed for user "postgres"

Performing system checks...

System check identified no issues (0 silenced).
Watching for file changes with StatReloader
Exception in thread django-main-thread:
Traceback (most recent call last):
  File "/root/RMS/Server/lvenv/lib/python3.8/site-packages/django/db/backends/base/base.py", line 219, in ensure_connection
    self.connect()
  File "/root/RMS/Server/lvenv/lib/python3.8/site-packages/django/utils/asyncio.py", line 33, in inner
    return func(*args, **kwargs)
  File "/root/RMS/Server/lvenv/lib/python3.8/site-packages/django/db/backends/base/base.py", line 200, in connect
    self.connection = self.get_new_connection(conn_params)
  File "/root/RMS/Server/lvenv/lib/python3.8/site-packages/django/utils/asyncio.py", line 33, in inner
    return func(*args, **kwargs)
  File "/root/RMS/Server/lvenv/lib/python3.8/site-packages/django/db/backends/postgresql/base.py", line 187, in get_new_connection
    connection = Database.connect(**conn_params)
  File "/root/RMS/Server/lvenv/lib/python3.8/site-packages/psycopg2/__init__.py", line 122, in connect
    conn = _connect(dsn, connection_factory=connection_factory, **kwasync)
psycopg2.OperationalError: FATAL:  password authentication failed for user "postgres"
FATAL:  password authentication failed for user "postgres"


The above exception was the direct cause of the following exception:

Traceback (most recent call last):
  File "/usr/lib/python3.8/threading.py", line 932, in _bootstrap_inner
    self.run()
  File "/usr/lib/python3.8/threading.py", line 870, in run
    self._target(*self._args, **self._kwargs)
  File "/root/RMS/Server/lvenv/lib/python3.8/site-packages/django/utils/autoreload.py", line 64, in wrapper
    fn(*args, **kwargs)
  File "/root/RMS/Server/lvenv/lib/python3.8/site-packages/django/core/management/commands/runserver.py", line 121, in inner_run
    self.check_migrations()
  File "/root/RMS/Server/lvenv/lib/python3.8/site-packages/django/core/management/base.py", line 486, in check_migrations
    executor = MigrationExecutor(connections[DEFAULT_DB_ALIAS])
  File "/root/RMS/Server/lvenv/lib/python3.8/site-packages/django/db/migrations/executor.py", line 18, in __init__
    self.loader = MigrationLoader(self.connection)
  File "/root/RMS/Server/lvenv/lib/python3.8/site-packages/django/db/migrations/loader.py", line 53, in __init__
    self.build_graph()
  File "/root/RMS/Server/lvenv/lib/python3.8/site-packages/django/db/migrations/loader.py", line 220, in build_graph
    self.applied_migrations = recorder.applied_migrations()
  File "/root/RMS/Server/lvenv/lib/python3.8/site-packages/django/db/migrations/recorder.py", line 77, in applied_migrations
    if self.has_table():
  File "/root/RMS/Server/lvenv/lib/python3.8/site-packages/django/db/migrations/recorder.py", line 55, in has_table
    with self.connection.cursor() as cursor:
  File "/root/RMS/Server/lvenv/lib/python3.8/site-packages/django/utils/asyncio.py", line 33, in inner
    return func(*args, **kwargs)
  File "/root/RMS/Server/lvenv/lib/python3.8/site-packages/django/db/backends/base/base.py", line 259, in cursor
    return self._cursor()
  File "/root/RMS/Server/lvenv/lib/python3.8/site-packages/django/db/backends/base/base.py", line 235, in _cursor
    self.ensure_connection()
  File "/root/RMS/Server/lvenv/lib/python3.8/site-packages/django/utils/asyncio.py", line 33, in inner
    return func(*args, **kwargs)
  File "/root/RMS/Server/lvenv/lib/python3.8/site-packages/django/db/backends/base/base.py", line 219, in ensure_connection
    self.connect()
  File "/root/RMS/Server/lvenv/lib/python3.8/site-packages/django/db/utils.py", line 90, in __exit__
    raise dj_exc_value.with_traceback(traceback) from exc_value
  File "/root/RMS/Server/lvenv/lib/python3.8/site-packages/django/db/backends/base/base.py", line 219, in ensure_connection
    self.connect()
  File "/root/RMS/Server/lvenv/lib/python3.8/site-packages/django/utils/asyncio.py", line 33, in inner
    return func(*args, **kwargs)
  File "/root/RMS/Server/lvenv/lib/python3.8/site-packages/django/db/backends/base/base.py", line 200, in connect
    self.connection = self.get_new_connection(conn_params)
  File "/root/RMS/Server/lvenv/lib/python3.8/site-packages/django/utils/asyncio.py", line 33, in inner
    return func(*args, **kwargs)
  File "/root/RMS/Server/lvenv/lib/python3.8/site-packages/django/db/backends/postgresql/base.py", line 187, in get_new_connection
    connection = Database.connect(**conn_params)
  File "/root/RMS/Server/lvenv/lib/python3.8/site-packages/psycopg2/__init__.py", line 122, in connect
    conn = _connect(dsn, connection_factory=connection_factory, **kwasync)
django.db.utils.OperationalError: FATAL:  password authentication failed for user "postgres"
FATAL:  password authentication failed for user "postgres"

Performing system checks...

System check identified no issues (0 silenced).
Watching for file changes with StatReloader
Exception in thread django-main-thread:
Traceback (most recent call last):
  File "/root/RMS/Server/lvenv/lib/python3.8/site-packages/django/db/backends/base/base.py", line 219, in ensure_connection
    self.connect()
  File "/root/RMS/Server/lvenv/lib/python3.8/site-packages/django/utils/asyncio.py", line 33, in inner
    return func(*args, **kwargs)
  File "/root/RMS/Server/lvenv/lib/python3.8/site-packages/django/db/backends/base/base.py", line 200, in connect
    self.connection = self.get_new_connection(conn_params)
  File "/root/RMS/Server/lvenv/lib/python3.8/site-packages/django/utils/asyncio.py", line 33, in inner
    return func(*args, **kwargs)
  File "/root/RMS/Server/lvenv/lib/python3.8/site-packages/django/db/backends/postgresql/base.py", line 187, in get_new_connection
    connection = Database.connect(**conn_params)
  File "/root/RMS/Server/lvenv/lib/python3.8/site-packages/psycopg2/__init__.py", line 122, in connect
    conn = _connect(dsn, connection_factory=connection_factory, **kwasync)
psycopg2.OperationalError: FATAL:  password authentication failed for user "postgres"
FATAL:  password authentication failed for user "postgres"


The above exception was the direct cause of the following exception:

Traceback (most recent call last):
  File "/usr/lib/python3.8/threading.py", line 932, in _bootstrap_inner
    self.run()
  File "/usr/lib/python3.8/threading.py", line 870, in run
    self._target(*self._args, **self._kwargs)
  File "/root/RMS/Server/lvenv/lib/python3.8/site-packages/django/utils/autoreload.py", line 64, in wrapper
    fn(*args, **kwargs)
  File "/root/RMS/Server/lvenv/lib/python3.8/site-packages/django/core/management/commands/runserver.py", line 121, in inner_run
    self.check_migrations()
  File "/root/RMS/Server/lvenv/lib/python3.8/site-packages/django/core/management/base.py", line 486, in check_migrations
    executor = MigrationExecutor(connections[DEFAULT_DB_ALIAS])
  File "/root/RMS/Server/lvenv/lib/python3.8/site-packages/django/db/migrations/executor.py", line 18, in __init__
    self.loader = MigrationLoader(self.connection)
  File "/root/RMS/Server/lvenv/lib/python3.8/site-packages/django/db/migrations/loader.py", line 53, in __init__
    self.build_graph()
  File "/root/RMS/Server/lvenv/lib/python3.8/site-packages/django/db/migrations/loader.py", line 220, in build_graph
    self.applied_migrations = recorder.applied_migrations()
  File "/root/RMS/Server/lvenv/lib/python3.8/site-packages/django/db/migrations/recorder.py", line 77, in applied_migrations
    if self.has_table():
  File "/root/RMS/Server/lvenv/lib/python3.8/site-packages/django/db/migrations/recorder.py", line 55, in has_table
    with self.connection.cursor() as cursor:
  File "/root/RMS/Server/lvenv/lib/python3.8/site-packages/django/utils/asyncio.py", line 33, in inner
    return func(*args, **kwargs)
  File "/root/RMS/Server/lvenv/lib/python3.8/site-packages/django/db/backends/base/base.py", line 259, in cursor
    return self._cursor()
  File "/root/RMS/Server/lvenv/lib/python3.8/site-packages/django/db/backends/base/base.py", line 235, in _cursor
    self.ensure_connection()
  File "/root/RMS/Server/lvenv/lib/python3.8/site-packages/django/utils/asyncio.py", line 33, in inner
    return func(*args, **kwargs)
  File "/root/RMS/Server/lvenv/lib/python3.8/site-packages/django/db/backends/base/base.py", line 219, in ensure_connection
    self.connect()
  File "/root/RMS/Server/lvenv/lib/python3.8/site-packages/django/db/utils.py", line 90, in __exit__
    raise dj_exc_value.with_traceback(traceback) from exc_value
  File "/root/RMS/Server/lvenv/lib/python3.8/site-packages/django/db/backends/base/base.py", line 219, in ensure_connection
    self.connect()
  File "/root/RMS/Server/lvenv/lib/python3.8/site-packages/django/utils/asyncio.py", line 33, in inner
    return func(*args, **kwargs)
  File "/root/RMS/Server/lvenv/lib/python3.8/site-packages/django/db/backends/base/base.py", line 200, in connect
    self.connection = self.get_new_connection(conn_params)
  File "/root/RMS/Server/lvenv/lib/python3.8/site-packages/django/utils/asyncio.py", line 33, in inner
    return func(*args, **kwargs)
  File "/root/RMS/Server/lvenv/lib/python3.8/site-packages/django/db/backends/postgresql/base.py", line 187, in get_new_connection
    connection = Database.connect(**conn_params)
  File "/root/RMS/Server/lvenv/lib/python3.8/site-packages/psycopg2/__init__.py", line 122, in connect
    conn = _connect(dsn, connection_factory=connection_factory, **kwasync)
django.db.utils.OperationalError: FATAL:  password authentication failed for user "postgres"
FATAL:  password authentication failed for user "postgres"

Performing system checks...

System check identified no issues (0 silenced).
Watching for file changes with StatReloader
Exception in thread django-main-thread:
Traceback (most recent call last):
  File "/usr/lib/python3.8/threading.py", line 932, in _bootstrap_inner
    self.run()
  File "/usr/lib/python3.8/threading.py", line 870, in run
    self._target(*self._args, **self._kwargs)
  File "/root/RMS/Server/lvenv/lib/python3.8/site-packages/django/utils/autoreload.py", line 64, in wrapper
    fn(*args, **kwargs)
  File "/root/RMS/Server/lvenv/lib/python3.8/site-packages/django/core/management/commands/runserver.py", line 139, in inner_run
    run(self.addr, int(self.port), handler,
  File "/root/RMS/Server/lvenv/lib/python3.8/site-packages/django/core/servers/basehttp.py", line 210, in run
    httpd = httpd_cls(server_address, WSGIRequestHandler, ipv6=ipv6)
  File "/root/RMS/Server/lvenv/lib/python3.8/site-packages/django/core/servers/basehttp.py", line 71, in __init__
    super().__init__(*args, **kwargs)
  File "/usr/lib/python3.8/socketserver.py", line 452, in __init__
    self.server_bind()
  File "/usr/lib/python3.8/wsgiref/simple_server.py", line 50, in server_bind
    HTTPServer.server_bind(self)
  File "/usr/lib/python3.8/http/server.py", line 138, in server_bind
    socketserver.TCPServer.server_bind(self)
  File "/usr/lib/python3.8/socketserver.py", line 466, in server_bind
    self.socket.bind(self.server_address)
OverflowError: bind(): port must be 0-65535.
Watching for file changes with StatReloader
[17/Feb/2022 18:57:15] "GET /user HTTP/1.1" 200 5706
[17/Feb/2022 18:57:21] "GET /user HTTP/1.1" 200 5706
[17/Feb/2022 18:57:22] "GET /user HTTP/1.1" 200 5706
[17/Feb/2022 18:59:12] "GET /user HTTP/1.1" 200 5706
[17/Feb/2022 20:13:15] "GET /user HTTP/1.1" 200 5706
Not Found: /favicon.ico
[17/Feb/2022 20:13:15] "GET /favicon.ico HTTP/1.1" 404 5819
Not Found: /
[17/Feb/2022 20:18:58] "GET / HTTP/1.1" 404 5772
[17/Feb/2022 20:19:13] "GET /user HTTP/1.1" 200 5706
[17/Feb/2022 21:39:22] code 400, message Bad request version ('À\x14À')
[17/Feb/2022 21:39:22] You're accessing the development server over HTTPS, but it only supports HTTP.

[17/Feb/2022 22:29:17] "GET /menu HTTP/1.1" 200 3025
[17/Feb/2022 22:29:17] "GET /menu HTTP/1.1" 200 3025
[17/Feb/2022 22:29:17] "GET /menuitem HTTP/1.1" 200 457
[17/Feb/2022 22:29:17] "GET /menuitem HTTP/1.1" 200 457
[17/Feb/2022 22:29:17] "GET /dishes HTTP/1.1" 200 412
[17/Feb/2022 22:29:17] "GET /dishes HTTP/1.1" 200 412
[17/Feb/2022 22:29:17] "GET /beverages HTTP/1.1" 200 570
[17/Feb/2022 22:29:18] "GET /beverages HTTP/1.1" 200 570
[17/Feb/2022 22:29:25] "GET /user HTTP/1.1" 200 5706
[17/Feb/2022 22:29:25] "GET /user HTTP/1.1" 200 5706
[17/Feb/2022 22:29:33] "GET /user HTTP/1.1" 200 5706
[17/Feb/2022 22:29:33] "GET /user HTTP/1.1" 200 5706
[17/Feb/2022 22:29:41] "GET /user HTTP/1.1" 200 5706
[17/Feb/2022 22:30:00] "GET /user HTTP/1.1" 200 5706
[17/Feb/2022 22:30:00] "GET /user HTTP/1.1" 200 5706
[17/Feb/2022 22:30:00] "GET /user HTTP/1.1" 200 5706
[17/Feb/2022 22:30:00] "GET /user HTTP/1.1" 200 5706
[17/Feb/2022 22:30:01] "GET /loyalty HTTP/1.1" 200 1164
[17/Feb/2022 22:30:01] "GET /loyalty HTTP/1.1" 200 1164
[17/Feb/2022 22:33:17] "GET /order HTTP/1.1" 200 2555
[17/Feb/2022 22:33:17] "GET /order HTTP/1.1" 200 2555
[17/Feb/2022 22:51:43] "GET /user HTTP/1.1" 200 5706
[17/Feb/2022 22:52:02] "GET /menuitem HTTP/1.1" 200 457
Not Found: /
[17/Feb/2022 22:52:11] "GET / HTTP/1.1" 404 5768
Not Found: /favicon.ico
[17/Feb/2022 22:52:12] "GET /favicon.ico HTTP/1.1" 404 5819
Watching for file changes with StatReloader
Not Found: /
[17/Feb/2022 22:57:25] "GET / HTTP/1.1" 404 5768
Not Found: /favicon.ico
[17/Feb/2022 22:57:25] "GET /favicon.ico HTTP/1.1" 404 5819
[17/Feb/2022 22:57:36] "GET /menu HTTP/1.1" 200 3025
[17/Feb/2022 22:57:37] "GET /menu HTTP/1.1" 200 3025
[17/Feb/2022 22:57:37] "GET /menuitem HTTP/1.1" 200 457
[17/Feb/2022 22:57:37] "GET /menuitem HTTP/1.1" 200 457
[17/Feb/2022 22:57:37] "GET /dishes HTTP/1.1" 200 412
[17/Feb/2022 22:57:37] "GET /dishes HTTP/1.1" 200 412
[17/Feb/2022 22:57:37] "GET /beverages HTTP/1.1" 200 570
[17/Feb/2022 22:57:37] "GET /beverages HTTP/1.1" 200 570
[17/Feb/2022 23:00:50] "GET /menu HTTP/1.1" 200 3025
[17/Feb/2022 23:00:50] "GET /menu HTTP/1.1" 200 3025
[17/Feb/2022 23:00:50] "GET /menuitem HTTP/1.1" 200 457
[17/Feb/2022 23:00:51] "GET /menuitem HTTP/1.1" 200 457
[17/Feb/2022 23:00:51] "GET /dishes HTTP/1.1" 200 412
[17/Feb/2022 23:00:51] "GET /dishes HTTP/1.1" 200 412
[17/Feb/2022 23:00:51] "GET /beverages HTTP/1.1" 200 570
[17/Feb/2022 23:00:51] "GET /beverages HTTP/1.1" 200 570
[17/Feb/2022 23:01:02] "GET /user HTTP/1.1" 200 5706
[17/Feb/2022 23:01:03] "GET /user HTTP/1.1" 200 5706
[17/Feb/2022 23:01:03] "GET /user HTTP/1.1" 200 5706
[17/Feb/2022 23:01:03] "GET /user HTTP/1.1" 200 5706
[17/Feb/2022 23:01:03] "GET /loyalty HTTP/1.1" 200 1164
[17/Feb/2022 23:01:03] "GET /loyalty HTTP/1.1" 200 1164
[17/Feb/2022 23:01:05] "GET /order HTTP/1.1" 200 2555
[17/Feb/2022 23:01:05] "GET /order HTTP/1.1" 200 2555
[17/Feb/2022 23:07:25] "GET /menu HTTP/1.1" 200 3025
[17/Feb/2022 23:07:25] "GET /menu HTTP/1.1" 200 3025
[17/Feb/2022 23:07:25] "GET /menuitem HTTP/1.1" 200 457
[17/Feb/2022 23:07:25] "GET /menuitem HTTP/1.1" 200 457
[17/Feb/2022 23:07:25] "GET /dishes HTTP/1.1" 200 412
[17/Feb/2022 23:07:25] "GET /dishes HTTP/1.1" 200 412
[17/Feb/2022 23:07:25] "GET /beverages HTTP/1.1" 200 570
[17/Feb/2022 23:07:25] "GET /beverages HTTP/1.1" 200 570
[17/Feb/2022 23:07:41] "GET /user HTTP/1.1" 200 5706
[17/Feb/2022 23:07:41] "GET /user HTTP/1.1" 200 5706
[17/Feb/2022 23:07:48] "GET /user HTTP/1.1" 200 5706
[17/Feb/2022 23:07:48] "GET /user HTTP/1.1" 200 5706
[17/Feb/2022 23:07:48] "GET /user HTTP/1.1" 200 5706
[17/Feb/2022 23:07:48] "GET /user HTTP/1.1" 200 5706
[17/Feb/2022 23:07:48] "GET /loyalty HTTP/1.1" 200 1164
[17/Feb/2022 23:07:48] "GET /loyalty HTTP/1.1" 200 1164
[17/Feb/2022 23:07:52,159] - Broken pipe from ('78.18.99.135', 61645)

[17/Feb/2022 23:10:47] "GET /menu HTTP/1.1" 200 3025
[17/Feb/2022 23:10:47] "GET /menu HTTP/1.1" 200 3025
[17/Feb/2022 23:10:47] "GET /menuitem HTTP/1.1" 200 457
[17/Feb/2022 23:10:47] "GET /menuitem HTTP/1.1" 200 457
[17/Feb/2022 23:10:47] "GET /dishes HTTP/1.1" 200 412
[17/Feb/2022 23:10:48] "GET /dishes HTTP/1.1" 200 412
[17/Feb/2022 23:10:48] "GET /beverages HTTP/1.1" 200 570
[17/Feb/2022 23:10:48] "GET /beverages HTTP/1.1" 200 570
[17/Feb/2022 23:10:53,043] - Broken pipe from ('78.18.99.135', 61664)

[17/Feb/2022 23:10:57] "GET /menu HTTP/1.1" 200 3025
[17/Feb/2022 23:10:57] "GET /menu HTTP/1.1" 200 3025
[17/Feb/2022 23:10:57] "GET /menuitem HTTP/1.1" 200 457
[17/Feb/2022 23:10:58] "GET /menuitem HTTP/1.1" 200 457
[17/Feb/2022 23:10:58] "GET /dishes HTTP/1.1" 200 412
[17/Feb/2022 23:10:58] "GET /dishes HTTP/1.1" 200 412
[17/Feb/2022 23:10:58] "GET /beverages HTTP/1.1" 200 570
[17/Feb/2022 23:10:58] "GET /beverages HTTP/1.1" 200 570
[17/Feb/2022 23:11:02] "GET /user HTTP/1.1" 200 5706
[17/Feb/2022 23:11:02] "GET /user HTTP/1.1" 200 5706
[17/Feb/2022 23:11:12] "GET /user HTTP/1.1" 200 5706
[17/Feb/2022 23:11:12] "GET /user HTTP/1.1" 200 5706
[17/Feb/2022 23:14:57] "GET /menu HTTP/1.1" 200 3025
[17/Feb/2022 23:14:57] "GET /menu HTTP/1.1" 200 3025
[17/Feb/2022 23:14:57] "GET /menuitem HTTP/1.1" 200 457
[17/Feb/2022 23:14:57] "GET /menuitem HTTP/1.1" 200 457
[17/Feb/2022 23:14:57] "GET /dishes HTTP/1.1" 200 412
[17/Feb/2022 23:14:58] "GET /dishes HTTP/1.1" 200 412
[17/Feb/2022 23:14:58] "GET /beverages HTTP/1.1" 200 570
[17/Feb/2022 23:14:58] "GET /beverages HTTP/1.1" 200 570
[17/Feb/2022 23:15:08] "GET /user HTTP/1.1" 200 5706
[17/Feb/2022 23:15:09] "GET /user HTTP/1.1" 200 5706
[17/Feb/2022 23:15:09] "GET /user HTTP/1.1" 200 5706
[17/Feb/2022 23:15:09] "GET /user HTTP/1.1" 200 5706
[17/Feb/2022 23:15:09] "GET /loyalty HTTP/1.1" 200 1164
[17/Feb/2022 23:15:09] "GET /loyalty HTTP/1.1" 200 1164
[17/Feb/2022 23:15:12] "GET /order HTTP/1.1" 200 2555
[17/Feb/2022 23:15:12] "GET /order HTTP/1.1" 200 2555
[17/Feb/2022 23:23:17] "GET /menuitem HTTP/1.1" 200 457
[17/Feb/2022 23:39:18] "GET /menu HTTP/1.1" 200 3025
[17/Feb/2022 23:39:19] "GET /menu HTTP/1.1" 200 3025
[17/Feb/2022 23:39:19] "GET /menuitem HTTP/1.1" 200 457
[17/Feb/2022 23:39:19] "GET /menuitem HTTP/1.1" 200 457
[17/Feb/2022 23:39:19] "GET /dishes HTTP/1.1" 200 412
[17/Feb/2022 23:39:19] "GET /dishes HTTP/1.1" 200 412
[17/Feb/2022 23:39:19] "GET /beverages HTTP/1.1" 200 570
[17/Feb/2022 23:39:19] "GET /beverages HTTP/1.1" 200 570
[17/Feb/2022 23:39:36] "GET /user HTTP/1.1" 200 5706
[17/Feb/2022 23:39:36] "GET /user HTTP/1.1" 200 5706
[17/Feb/2022 23:39:45] "GET /user HTTP/1.1" 200 5706
[17/Feb/2022 23:39:45] "GET /user HTTP/1.1" 200 5706
[17/Feb/2022 23:39:49] "GET /user HTTP/1.1" 200 5706
[17/Feb/2022 23:39:50] "GET /user HTTP/1.1" 200 5706
[17/Feb/2022 23:39:53] "GET /user HTTP/1.1" 200 5706
[17/Feb/2022 23:39:53] "GET /user HTTP/1.1" 200 5706
[17/Feb/2022 23:40:10] "POST /user HTTP/1.1" 200 20
[17/Feb/2022 23:40:10] "GET /user HTTP/1.1" 200 5825
[17/Feb/2022 23:40:10] "GET /user HTTP/1.1" 200 5825
[17/Feb/2022 23:40:11] "POST /loyalty HTTP/1.1" 200 20
[17/Feb/2022 23:40:21] "GET /menuitem HTTP/1.1" 200 457
[17/Feb/2022 23:40:24] "GET /user HTTP/1.1" 200 5825
[17/Feb/2022 23:45:07] code 400, message Bad HTTP/0.9 request type ('\x03\x00\x00/*à\x00\x00\x00\x00\x00Cookie:')
[17/Feb/2022 23:45:07] "  /*à     Cookie: mstshash=Administr" 400 -
[17/Feb/2022 23:46:41] "GET /user HTTP/1.1" 200 5825
[17/Feb/2022 23:46:41] "GET /user HTTP/1.1" 200 5825
[17/Feb/2022 23:46:41] "GET /user HTTP/1.1" 200 5825
[17/Feb/2022 23:46:41] "GET /user HTTP/1.1" 200 5825
[17/Feb/2022 23:46:41] "GET /loyalty HTTP/1.1" 200 1220
[17/Feb/2022 23:46:41] "GET /loyalty HTTP/1.1" 200 1220
[17/Feb/2022 23:47:05] "GET /employeesalary HTTP/1.1" 200 324
[17/Feb/2022 23:47:41] "GET /user HTTP/1.1" 200 5825
[17/Feb/2022 23:47:41] "GET /user HTTP/1.1" 200 5825
[17/Feb/2022 23:47:41] "GET /user HTTP/1.1" 200 5825
[17/Feb/2022 23:47:42] "GET /user HTTP/1.1" 200 5825
[17/Feb/2022 23:47:42] "GET /employeesalary HTTP/1.1" 200 324
[17/Feb/2022 23:47:42] "GET /employeesalary HTTP/1.1" 200 324
[17/Feb/2022 23:49:37] "PATCH /menu HTTP/1.1" 200 19
[17/Feb/2022 23:49:37] "GET /menu HTTP/1.1" 200 3043
[17/Feb/2022 23:49:37] "GET /menu HTTP/1.1" 200 3043
[17/Feb/2022 23:50:03] "GET /menu HTTP/1.1" 200 3043
[17/Feb/2022 23:50:03] "GET /menu HTTP/1.1" 200 3043
[17/Feb/2022 23:50:03] "GET /menuitem HTTP/1.1" 200 457
[17/Feb/2022 23:50:03] "GET /menuitem HTTP/1.1" 200 457
[17/Feb/2022 23:50:03] "GET /dishes HTTP/1.1" 200 412
[17/Feb/2022 23:50:03] "GET /dishes HTTP/1.1" 200 412
[17/Feb/2022 23:50:03] "GET /beverages HTTP/1.1" 200 570
[17/Feb/2022 23:50:03] "GET /beverages HTTP/1.1" 200 570
[17/Feb/2022 23:50:11] "GET /user HTTP/1.1" 200 5825
[17/Feb/2022 23:50:11] "GET /user HTTP/1.1" 200 5825
[17/Feb/2022 23:50:11] "GET /user HTTP/1.1" 200 5825
[17/Feb/2022 23:50:11] "GET /user HTTP/1.1" 200 5825
[17/Feb/2022 23:50:11] "GET /loyalty HTTP/1.1" 200 1220
[17/Feb/2022 23:50:11] "GET /loyalty HTTP/1.1" 200 1220
Not Found: /
[18/Feb/2022 00:03:53] "GET / HTTP/1.1" 404 5767
[18/Feb/2022 01:10:49] "GET /menu HTTP/1.1" 200 3043
[18/Feb/2022 01:10:49] "GET /menu HTTP/1.1" 200 3043
[18/Feb/2022 01:10:49] "GET /menuitem HTTP/1.1" 200 457
[18/Feb/2022 01:10:49] "GET /menuitem HTTP/1.1" 200 457
[18/Feb/2022 01:10:49] "GET /dishes HTTP/1.1" 200 412
[18/Feb/2022 01:10:49] "GET /dishes HTTP/1.1" 200 412
[18/Feb/2022 01:10:49] "GET /beverages HTTP/1.1" 200 570
[18/Feb/2022 01:10:49] "GET /beverages HTTP/1.1" 200 570
[18/Feb/2022 01:10:53,665] - Broken pipe from ('78.18.99.135', 62296)

[18/Feb/2022 02:43:39] code 400, message Bad HTTP/0.9 request type ('\x03\x00\x00/*à\x00\x00\x00\x00\x00Cookie:')
[18/Feb/2022 02:43:39] "  /*à     Cookie: mstshash=Administr" 400 -
Not Found: /
[18/Feb/2022 03:35:22] "GET / HTTP/1.1" 404 5772
Not Found: /
[18/Feb/2022 04:15:42] "GET / HTTP/1.1" 404 5765
[18/Feb/2022 04:15:42,830] - Broken pipe from ('185.189.182.234', 40360)

[18/Feb/2022 07:09:31] "GET /admin/ HTTP/1.1" 302 0
[18/Feb/2022 11:04:19,351] - Broken pipe from ('162.142.125.210', 55048)

Not Found: /
[18/Feb/2022 11:04:20] "GET / HTTP/1.1" 404 5772
[18/Feb/2022 11:04:20,525] - Broken pipe from ('162.142.125.210', 40410)

Not Found: /
[18/Feb/2022 11:04:20] "GET / HTTP/1.1" 404 5772
[18/Feb/2022 11:04:20] code 505, message Invalid HTTP version (2.0)
[18/Feb/2022 11:04:20] "PRI * HTTP/2.0" 505 -
Not Found: /
[18/Feb/2022 11:52:02] "HEAD / HTTP/1.0" 404 5766
Not Found: /
[18/Feb/2022 16:27:06] "GET / HTTP/1.0" 404 5765
Watching for file changes with StatReloader
Watching for file changes with StatReloader
Watching for file changes with StatReloader
Watching for file changes with StatReloader
Watching for file changes with StatReloader
[18/Feb/2022 16:56:59] "GET /user HTTP/1.1" 200 5825
Not Found: /
[18/Feb/2022 16:57:02] "GET / HTTP/1.1" 404 4756
Internal Server Error: /menuitem
Traceback (most recent call last):
  File "/root/RMS/Server/lvenv/lib/python3.8/site-packages/django/core/handlers/exception.py", line 47, in inner
    response = get_response(request)
  File "/root/RMS/Server/lvenv/lib/python3.8/site-packages/django/core/handlers/base.py", line 181, in _get_response
    response = wrapped_callback(request, *callback_args, **callback_kwargs)
  File "/root/RMS/Server/lvenv/lib/python3.8/site-packages/django/views/decorators/csrf.py", line 54, in wrapped_view
    return view_func(*args, **kwargs)
  File "/root/CS4227/CS4227-Application/Server/Restuarant/views.py", line 223, in menuitemApi
    return JsonResponse(menuitemSerializer.data, safe=False)
  File "/root/RMS/Server/lvenv/lib/python3.8/site-packages/rest_framework/serializers.py", line 745, in data
    ret = super().data
  File "/root/RMS/Server/lvenv/lib/python3.8/site-packages/rest_framework/serializers.py", line 246, in data
    self._data = self.to_representation(self.instance)
  File "/root/RMS/Server/lvenv/lib/python3.8/site-packages/rest_framework/serializers.py", line 663, in to_representation
    return [
  File "/root/RMS/Server/lvenv/lib/python3.8/site-packages/rest_framework/serializers.py", line 664, in <listcomp>
    self.child.to_representation(item) for item in iterable
  File "/root/RMS/Server/lvenv/lib/python3.8/site-packages/rest_framework/serializers.py", line 500, in to_representation
    for field in fields:
  File "/root/RMS/Server/lvenv/lib/python3.8/site-packages/rest_framework/serializers.py", line 361, in _readable_fields
    for field in self.fields.values():
  File "/root/RMS/Server/lvenv/lib/python3.8/site-packages/django/utils/functional.py", line 48, in __get__
    res = instance.__dict__[self.name] = self.func(instance)
  File "/root/RMS/Server/lvenv/lib/python3.8/site-packages/rest_framework/serializers.py", line 349, in fields
    for key, value in self.get_fields().items():
  File "/root/RMS/Server/lvenv/lib/python3.8/site-packages/rest_framework/serializers.py", line 1053, in get_fields
    field_class, field_kwargs = self.build_field(
  File "/root/RMS/Server/lvenv/lib/python3.8/site-packages/rest_framework/serializers.py", line 1199, in build_field
    return self.build_unknown_field(field_name, model_class)
  File "/root/RMS/Server/lvenv/lib/python3.8/site-packages/rest_framework/serializers.py", line 1317, in build_unknown_field
    raise ImproperlyConfigured(
django.core.exceptions.ImproperlyConfigured: Field name `dish_bev_id` is not valid for model `MenuItem`.
[18/Feb/2022 16:58:10] "GET /menuitem HTTP/1.1" 500 114126
Not Found: /favicon.ico
[18/Feb/2022 16:58:10] "GET /favicon.ico HTTP/1.1" 404 4807
Not Found: /users
[18/Feb/2022 16:58:20] "GET /users HTTP/1.1" 404 4789
[18/Feb/2022 16:58:27] "GET /user HTTP/1.1" 200 5825
Internal Server Error: /menuitem
Traceback (most recent call last):
  File "/root/RMS/Server/lvenv/lib/python3.8/site-packages/django/core/handlers/exception.py", line 47, in inner
    response = get_response(request)
  File "/root/RMS/Server/lvenv/lib/python3.8/site-packages/django/core/handlers/base.py", line 181, in _get_response
    response = wrapped_callback(request, *callback_args, **callback_kwargs)
  File "/root/RMS/Server/lvenv/lib/python3.8/site-packages/django/views/decorators/csrf.py", line 54, in wrapped_view
    return view_func(*args, **kwargs)
  File "/root/CS4227/CS4227-Application/Server/Restuarant/views.py", line 223, in menuitemApi
    return JsonResponse(menuitemSerializer.data, safe=False)
  File "/root/RMS/Server/lvenv/lib/python3.8/site-packages/rest_framework/serializers.py", line 745, in data
    ret = super().data
  File "/root/RMS/Server/lvenv/lib/python3.8/site-packages/rest_framework/serializers.py", line 246, in data
    self._data = self.to_representation(self.instance)
  File "/root/RMS/Server/lvenv/lib/python3.8/site-packages/rest_framework/serializers.py", line 663, in to_representation
    return [
  File "/root/RMS/Server/lvenv/lib/python3.8/site-packages/rest_framework/serializers.py", line 664, in <listcomp>
    self.child.to_representation(item) for item in iterable
  File "/root/RMS/Server/lvenv/lib/python3.8/site-packages/rest_framework/serializers.py", line 500, in to_representation
    for field in fields:
  File "/root/RMS/Server/lvenv/lib/python3.8/site-packages/rest_framework/serializers.py", line 361, in _readable_fields
    for field in self.fields.values():
  File "/root/RMS/Server/lvenv/lib/python3.8/site-packages/django/utils/functional.py", line 48, in __get__
    res = instance.__dict__[self.name] = self.func(instance)
  File "/root/RMS/Server/lvenv/lib/python3.8/site-packages/rest_framework/serializers.py", line 349, in fields
    for key, value in self.get_fields().items():
  File "/root/RMS/Server/lvenv/lib/python3.8/site-packages/rest_framework/serializers.py", line 1053, in get_fields
    field_class, field_kwargs = self.build_field(
  File "/root/RMS/Server/lvenv/lib/python3.8/site-packages/rest_framework/serializers.py", line 1199, in build_field
    return self.build_unknown_field(field_name, model_class)
  File "/root/RMS/Server/lvenv/lib/python3.8/site-packages/rest_framework/serializers.py", line 1317, in build_unknown_field
    raise ImproperlyConfigured(
django.core.exceptions.ImproperlyConfigured: Field name `dish_bev_id` is not valid for model `MenuItem`.
[18/Feb/2022 16:58:30] "GET /menuitem HTTP/1.1" 500 114126
[18/Feb/2022 16:59:13] "GET /employeesalary HTTP/1.1" 200 324
Not Found: /favicon.ico
[18/Feb/2022 16:59:13] "GET /favicon.ico HTTP/1.1" 404 4807
Internal Server Error: /menuitem
Traceback (most recent call last):
  File "/root/RMS/Server/lvenv/lib/python3.8/site-packages/django/core/handlers/exception.py", line 47, in inner
    response = get_response(request)
  File "/root/RMS/Server/lvenv/lib/python3.8/site-packages/django/core/handlers/base.py", line 181, in _get_response
    response = wrapped_callback(request, *callback_args, **callback_kwargs)
  File "/root/RMS/Server/lvenv/lib/python3.8/site-packages/django/views/decorators/csrf.py", line 54, in wrapped_view
    return view_func(*args, **kwargs)
  File "/root/CS4227/CS4227-Application/Server/Restuarant/views.py", line 223, in menuitemApi
    return JsonResponse(menuitemSerializer.data, safe=False)
  File "/root/RMS/Server/lvenv/lib/python3.8/site-packages/rest_framework/serializers.py", line 745, in data
    ret = super().data
  File "/root/RMS/Server/lvenv/lib/python3.8/site-packages/rest_framework/serializers.py", line 246, in data
    self._data = self.to_representation(self.instance)
  File "/root/RMS/Server/lvenv/lib/python3.8/site-packages/rest_framework/serializers.py", line 663, in to_representation
    return [
  File "/root/RMS/Server/lvenv/lib/python3.8/site-packages/rest_framework/serializers.py", line 664, in <listcomp>
    self.child.to_representation(item) for item in iterable
  File "/root/RMS/Server/lvenv/lib/python3.8/site-packages/rest_framework/serializers.py", line 500, in to_representation
    for field in fields:
  File "/root/RMS/Server/lvenv/lib/python3.8/site-packages/rest_framework/serializers.py", line 361, in _readable_fields
    for field in self.fields.values():
  File "/root/RMS/Server/lvenv/lib/python3.8/site-packages/django/utils/functional.py", line 48, in __get__
    res = instance.__dict__[self.name] = self.func(instance)
  File "/root/RMS/Server/lvenv/lib/python3.8/site-packages/rest_framework/serializers.py", line 349, in fields
    for key, value in self.get_fields().items():
  File "/root/RMS/Server/lvenv/lib/python3.8/site-packages/rest_framework/serializers.py", line 1053, in get_fields
    field_class, field_kwargs = self.build_field(
  File "/root/RMS/Server/lvenv/lib/python3.8/site-packages/rest_framework/serializers.py", line 1199, in build_field
    return self.build_unknown_field(field_name, model_class)
  File "/root/RMS/Server/lvenv/lib/python3.8/site-packages/rest_framework/serializers.py", line 1317, in build_unknown_field
    raise ImproperlyConfigured(
django.core.exceptions.ImproperlyConfigured: Field name `dish_bev_id` is not valid for model `MenuItem`.
[18/Feb/2022 16:59:21] "GET /menuitem HTTP/1.1" 500 114857
[18/Feb/2022 17:02:49,595] - Broken pipe from ('79.140.208.90', 40288)

[18/Feb/2022 17:02:49,596] - Broken pipe from ('79.140.208.90', 40286)

Internal Server Error: /menuitem
Traceback (most recent call last):
  File "/root/RMS/Server/lvenv/lib/python3.8/site-packages/django/core/handlers/exception.py", line 47, in inner
    response = get_response(request)
  File "/root/RMS/Server/lvenv/lib/python3.8/site-packages/django/core/handlers/base.py", line 181, in _get_response
    response = wrapped_callback(request, *callback_args, **callback_kwargs)
  File "/root/RMS/Server/lvenv/lib/python3.8/site-packages/django/views/decorators/csrf.py", line 54, in wrapped_view
    return view_func(*args, **kwargs)
  File "/root/CS4227/CS4227-Application/Server/Restuarant/views.py", line 223, in menuitemApi
    return JsonResponse(menuitemSerializer.data, safe=False)
  File "/root/RMS/Server/lvenv/lib/python3.8/site-packages/rest_framework/serializers.py", line 745, in data
    ret = super().data
  File "/root/RMS/Server/lvenv/lib/python3.8/site-packages/rest_framework/serializers.py", line 246, in data
    self._data = self.to_representation(self.instance)
  File "/root/RMS/Server/lvenv/lib/python3.8/site-packages/rest_framework/serializers.py", line 663, in to_representation
    return [
  File "/root/RMS/Server/lvenv/lib/python3.8/site-packages/rest_framework/serializers.py", line 664, in <listcomp>
    self.child.to_representation(item) for item in iterable
  File "/root/RMS/Server/lvenv/lib/python3.8/site-packages/rest_framework/serializers.py", line 500, in to_representation
    for field in fields:
  File "/root/RMS/Server/lvenv/lib/python3.8/site-packages/rest_framework/serializers.py", line 361, in _readable_fields
    for field in self.fields.values():
  File "/root/RMS/Server/lvenv/lib/python3.8/site-packages/django/utils/functional.py", line 48, in __get__
    res = instance.__dict__[self.name] = self.func(instance)
  File "/root/RMS/Server/lvenv/lib/python3.8/site-packages/rest_framework/serializers.py", line 349, in fields
    for key, value in self.get_fields().items():
  File "/root/RMS/Server/lvenv/lib/python3.8/site-packages/rest_framework/serializers.py", line 1053, in get_fields
    field_class, field_kwargs = self.build_field(
  File "/root/RMS/Server/lvenv/lib/python3.8/site-packages/rest_framework/serializers.py", line 1199, in build_field
    return self.build_unknown_field(field_name, model_class)
  File "/root/RMS/Server/lvenv/lib/python3.8/site-packages/rest_framework/serializers.py", line 1317, in build_unknown_field
    raise ImproperlyConfigured(
django.core.exceptions.ImproperlyConfigured: Field name `dish_bev_id` is not valid for model `MenuItem`.
[18/Feb/2022 17:04:19] "GET /menuitem HTTP/1.1" 500 113893
/root/CS4227/CS4227-Application/Server/Restuarant/serializers.py changed, reloading.
Performing system checks...

System check identified no issues (0 silenced).
February 18, 2022 - 16:56:31
Django version 3.2.9, using settings 'Server.settings'
Starting development server at http://0.0.0.0:8000/
Quit the server with CONTROL-C.
Watching for file changes with StatReloader
/root/CS4227/CS4227-Application/Server/Restuarant/serializers.py changed, reloading.
Performing system checks...

System check identified no issues (0 silenced).
February 18, 2022 - 17:05:58
Django version 3.2.9, using settings 'Server.settings'
Starting development server at http://0.0.0.0:8000/
Quit the server with CONTROL-C.
Watching for file changes with StatReloader
Internal Server Error: /menuitem
Traceback (most recent call last):
  File "/root/RMS/Server/lvenv/lib/python3.8/site-packages/django/core/handlers/exception.py", line 47, in inner
    response = get_response(request)
  File "/root/RMS/Server/lvenv/lib/python3.8/site-packages/django/core/handlers/base.py", line 181, in _get_response
    response = wrapped_callback(request, *callback_args, **callback_kwargs)
  File "/root/RMS/Server/lvenv/lib/python3.8/site-packages/django/views/decorators/csrf.py", line 54, in wrapped_view
    return view_func(*args, **kwargs)
  File "/root/CS4227/CS4227-Application/Server/Restuarant/views.py", line 223, in menuitemApi
    return JsonResponse(menuitemSerializer.data, safe=False)
  File "/root/RMS/Server/lvenv/lib/python3.8/site-packages/rest_framework/serializers.py", line 745, in data
    ret = super().data
  File "/root/RMS/Server/lvenv/lib/python3.8/site-packages/rest_framework/serializers.py", line 246, in data
    self._data = self.to_representation(self.instance)
  File "/root/RMS/Server/lvenv/lib/python3.8/site-packages/rest_framework/serializers.py", line 663, in to_representation
    return [
  File "/root/RMS/Server/lvenv/lib/python3.8/site-packages/rest_framework/serializers.py", line 664, in <listcomp>
    self.child.to_representation(item) for item in iterable
  File "/root/RMS/Server/lvenv/lib/python3.8/site-packages/rest_framework/serializers.py", line 500, in to_representation
    for field in fields:
  File "/root/RMS/Server/lvenv/lib/python3.8/site-packages/rest_framework/serializers.py", line 361, in _readable_fields
    for field in self.fields.values():
  File "/root/RMS/Server/lvenv/lib/python3.8/site-packages/django/utils/functional.py", line 48, in __get__
    res = instance.__dict__[self.name] = self.func(instance)
  File "/root/RMS/Server/lvenv/lib/python3.8/site-packages/rest_framework/serializers.py", line 349, in fields
    for key, value in self.get_fields().items():
  File "/root/RMS/Server/lvenv/lib/python3.8/site-packages/rest_framework/serializers.py", line 1053, in get_fields
    field_class, field_kwargs = self.build_field(
  File "/root/RMS/Server/lvenv/lib/python3.8/site-packages/rest_framework/serializers.py", line 1199, in build_field
    return self.build_unknown_field(field_name, model_class)
  File "/root/RMS/Server/lvenv/lib/python3.8/site-packages/rest_framework/serializers.py", line 1317, in build_unknown_field
    raise ImproperlyConfigured(
django.core.exceptions.ImproperlyConfigured: Field name `alcoholic` is not valid for model `MenuItem`.
[18/Feb/2022 17:07:28] "GET /menuitem HTTP/1.1" 500 114062
Watching for file changes with StatReloader
[18/Feb/2022 17:10:26] "GET /menuitem HTTP/1.1" 200 893
[18/Feb/2022 17:11:21] "GET /menuitem HTTP/1.1" 200 893
[18/Feb/2022 17:11:24] "GET /menuitem HTTP/1.1" 200 893
Not Found: /
[18/Feb/2022 17:13:13] "GET / HTTP/1.1" 404 4756
Not Found: /users
[18/Feb/2022 17:14:19] "GET /users HTTP/1.1" 404 4789
[18/Feb/2022 17:14:34] "GET /order HTTP/1.1" 200 2555
[18/Feb/2022 17:14:39] "GET /loyalty HTTP/1.1" 200 1220
[18/Feb/2022 17:14:44] "GET /employeesalary HTTP/1.1" 200 324
Internal Server Error: /orderlineitem
Traceback (most recent call last):
  File "/root/RMS/Server/lvenv/lib/python3.8/site-packages/django/core/handlers/exception.py", line 47, in inner
    response = get_response(request)
  File "/root/RMS/Server/lvenv/lib/python3.8/site-packages/django/core/handlers/base.py", line 181, in _get_response
    response = wrapped_callback(request, *callback_args, **callback_kwargs)
  File "/root/RMS/Server/lvenv/lib/python3.8/site-packages/django/views/decorators/csrf.py", line 54, in wrapped_view
    return view_func(*args, **kwargs)
  File "/root/CS4227/CS4227-Application/Server/Restuarant/views.py", line 258, in orderlineitemsApi
    return JsonResponse(orderLineItemsSerializer.data, safe=False)
  File "/root/RMS/Server/lvenv/lib/python3.8/site-packages/rest_framework/serializers.py", line 745, in data
    ret = super().data
  File "/root/RMS/Server/lvenv/lib/python3.8/site-packages/rest_framework/serializers.py", line 246, in data
    self._data = self.to_representation(self.instance)
  File "/root/RMS/Server/lvenv/lib/python3.8/site-packages/rest_framework/serializers.py", line 663, in to_representation
    return [
  File "/root/RMS/Server/lvenv/lib/python3.8/site-packages/rest_framework/serializers.py", line 664, in <listcomp>
    self.child.to_representation(item) for item in iterable
  File "/root/RMS/Server/lvenv/lib/python3.8/site-packages/rest_framework/serializers.py", line 500, in to_representation
    for field in fields:
  File "/root/RMS/Server/lvenv/lib/python3.8/site-packages/rest_framework/serializers.py", line 361, in _readable_fields
    for field in self.fields.values():
  File "/root/RMS/Server/lvenv/lib/python3.8/site-packages/django/utils/functional.py", line 48, in __get__
    res = instance.__dict__[self.name] = self.func(instance)
  File "/root/RMS/Server/lvenv/lib/python3.8/site-packages/rest_framework/serializers.py", line 349, in fields
    for key, value in self.get_fields().items():
  File "/root/RMS/Server/lvenv/lib/python3.8/site-packages/rest_framework/serializers.py", line 1053, in get_fields
    field_class, field_kwargs = self.build_field(
  File "/root/RMS/Server/lvenv/lib/python3.8/site-packages/rest_framework/serializers.py", line 1199, in build_field
    return self.build_unknown_field(field_name, model_class)
  File "/root/RMS/Server/lvenv/lib/python3.8/site-packages/rest_framework/serializers.py", line 1317, in build_unknown_field
    raise ImproperlyConfigured(
django.core.exceptions.ImproperlyConfigured: Field name `orderlineitems_id` is not valid for model `OrderLineItems`.
[18/Feb/2022 17:14:50] "GET /orderlineitem HTTP/1.1" 500 115736
[18/Feb/2022 17:15:20] "GET /menuitem HTTP/1.1" 200 893
Not Found: /stockitem
[18/Feb/2022 17:15:23] "GET /stockitem HTTP/1.1" 404 4801
[18/Feb/2022 17:15:31] "GET /stockitems HTTP/1.1" 200 2
[18/Feb/2022 17:15:38] "GET /stockitem/1 HTTP/1.1" 200 2
[18/Feb/2022 17:15:43] "GET /user/1 HTTP/1.1" 200 5825
[18/Feb/2022 17:15:50] "GET /stockitems HTTP/1.1" 200 2
[18/Feb/2022 17:20:27] "GET /user HTTP/1.1" 200 5825
Internal Server Error: /orderlineitem
Traceback (most recent call last):
  File "/root/RMS/Server/lvenv/lib/python3.8/site-packages/django/core/handlers/exception.py", line 47, in inner
    response = get_response(request)
  File "/root/RMS/Server/lvenv/lib/python3.8/site-packages/django/core/handlers/base.py", line 181, in _get_response
    response = wrapped_callback(request, *callback_args, **callback_kwargs)
  File "/root/RMS/Server/lvenv/lib/python3.8/site-packages/django/views/decorators/csrf.py", line 54, in wrapped_view
    return view_func(*args, **kwargs)
  File "/root/CS4227/CS4227-Application/Server/Restuarant/views.py", line 258, in orderlineitemsApi
    return JsonResponse(orderLineItemsSerializer.data, safe=False)
  File "/root/RMS/Server/lvenv/lib/python3.8/site-packages/rest_framework/serializers.py", line 745, in data
    ret = super().data
  File "/root/RMS/Server/lvenv/lib/python3.8/site-packages/rest_framework/serializers.py", line 246, in data
    self._data = self.to_representation(self.instance)
  File "/root/RMS/Server/lvenv/lib/python3.8/site-packages/rest_framework/serializers.py", line 663, in to_representation
    return [
  File "/root/RMS/Server/lvenv/lib/python3.8/site-packages/rest_framework/serializers.py", line 664, in <listcomp>
    self.child.to_representation(item) for item in iterable
  File "/root/RMS/Server/lvenv/lib/python3.8/site-packages/rest_framework/serializers.py", line 500, in to_representation
    for field in fields:
  File "/root/RMS/Server/lvenv/lib/python3.8/site-packages/rest_framework/serializers.py", line 361, in _readable_fields
    for field in self.fields.values():
  File "/root/RMS/Server/lvenv/lib/python3.8/site-packages/django/utils/functional.py", line 48, in __get__
    res = instance.__dict__[self.name] = self.func(instance)
  File "/root/RMS/Server/lvenv/lib/python3.8/site-packages/rest_framework/serializers.py", line 349, in fields
    for key, value in self.get_fields().items():
  File "/root/RMS/Server/lvenv/lib/python3.8/site-packages/rest_framework/serializers.py", line 1053, in get_fields
    field_class, field_kwargs = self.build_field(
  File "/root/RMS/Server/lvenv/lib/python3.8/site-packages/rest_framework/serializers.py", line 1199, in build_field
    return self.build_unknown_field(field_name, model_class)
  File "/root/RMS/Server/lvenv/lib/python3.8/site-packages/rest_framework/serializers.py", line 1317, in build_unknown_field
    raise ImproperlyConfigured(
django.core.exceptions.ImproperlyConfigured: Field name `orderlineitems_id` is not valid for model `OrderLineItems`.
[18/Feb/2022 17:20:34] "GET /orderlineitem HTTP/1.1" 500 115503
Not Found: /favicon.ico
[18/Feb/2022 17:20:34] "GET /favicon.ico HTTP/1.1" 404 4807
/root/CS4227/CS4227-Application/Server/Restuarant/models.py changed, reloading.
Performing system checks...

System check identified no issues (0 silenced).
February 18, 2022 - 17:10:13
Django version 3.2.9, using settings 'Server.settings'
Starting development server at http://0.0.0.0:8000/
Quit the server with CONTROL-C.
Watching for file changes with StatReloader
/root/CS4227/CS4227-Application/Server/Restuarant/models.py changed, reloading.
Performing system checks...

System check identified no issues (0 silenced).
February 18, 2022 - 17:21:12
Django version 3.2.9, using settings 'Server.settings'
Starting development server at http://0.0.0.0:8000/
Quit the server with CONTROL-C.
Watching for file changes with StatReloader
Internal Server Error: /orderlineitem
Traceback (most recent call last):
  File "/root/RMS/Server/lvenv/lib/python3.8/site-packages/django/db/backends/utils.py", line 84, in _execute
    return self.cursor.execute(sql, params)
psycopg2.errors.UndefinedColumn: column Restuarant_orderlineitems.orderlineitems_id does not exist
LINE 1: SELECT "Restuarant_orderlineitems"."orderlineitems_id", "Res...
               ^


The above exception was the direct cause of the following exception:

Traceback (most recent call last):
  File "/root/RMS/Server/lvenv/lib/python3.8/site-packages/django/core/handlers/exception.py", line 47, in inner
    response = get_response(request)
  File "/root/RMS/Server/lvenv/lib/python3.8/site-packages/django/core/handlers/base.py", line 181, in _get_response
    response = wrapped_callback(request, *callback_args, **callback_kwargs)
  File "/root/RMS/Server/lvenv/lib/python3.8/site-packages/django/views/decorators/csrf.py", line 54, in wrapped_view
    return view_func(*args, **kwargs)
  File "/root/CS4227/CS4227-Application/Server/Restuarant/views.py", line 258, in orderlineitemsApi
    return JsonResponse(orderLineItemsSerializer.data, safe=False)
  File "/root/RMS/Server/lvenv/lib/python3.8/site-packages/rest_framework/serializers.py", line 745, in data
    ret = super().data
  File "/root/RMS/Server/lvenv/lib/python3.8/site-packages/rest_framework/serializers.py", line 246, in data
    self._data = self.to_representation(self.instance)
  File "/root/RMS/Server/lvenv/lib/python3.8/site-packages/rest_framework/serializers.py", line 663, in to_representation
    return [
  File "/root/RMS/Server/lvenv/lib/python3.8/site-packages/django/db/models/query.py", line 280, in __iter__
    self._fetch_all()
  File "/root/RMS/Server/lvenv/lib/python3.8/site-packages/django/db/models/query.py", line 1324, in _fetch_all
    self._result_cache = list(self._iterable_class(self))
  File "/root/RMS/Server/lvenv/lib/python3.8/site-packages/django/db/models/query.py", line 51, in __iter__
    results = compiler.execute_sql(chunked_fetch=self.chunked_fetch, chunk_size=self.chunk_size)
  File "/root/RMS/Server/lvenv/lib/python3.8/site-packages/django/db/models/sql/compiler.py", line 1175, in execute_sql
    cursor.execute(sql, params)
  File "/root/RMS/Server/lvenv/lib/python3.8/site-packages/django/db/backends/utils.py", line 98, in execute
    return super().execute(sql, params)
  File "/root/RMS/Server/lvenv/lib/python3.8/site-packages/django/db/backends/utils.py", line 66, in execute
    return self._execute_with_wrappers(sql, params, many=False, executor=self._execute)
  File "/root/RMS/Server/lvenv/lib/python3.8/site-packages/django/db/backends/utils.py", line 75, in _execute_with_wrappers
    return executor(sql, params, many, context)
  File "/root/RMS/Server/lvenv/lib/python3.8/site-packages/django/db/backends/utils.py", line 84, in _execute
    return self.cursor.execute(sql, params)
  File "/root/RMS/Server/lvenv/lib/python3.8/site-packages/django/db/utils.py", line 90, in __exit__
    raise dj_exc_value.with_traceback(traceback) from exc_value
  File "/root/RMS/Server/lvenv/lib/python3.8/site-packages/django/db/backends/utils.py", line 84, in _execute
    return self.cursor.execute(sql, params)
django.db.utils.ProgrammingError: column Restuarant_orderlineitems.orderlineitems_id does not exist
LINE 1: SELECT "Restuarant_orderlineitems"."orderlineitems_id", "Res...
               ^

[18/Feb/2022 17:21:42] "GET /orderlineitem HTTP/1.1" 500 129616
Not Found: /favicon.ico
[18/Feb/2022 17:21:43] "GET /favicon.ico HTTP/1.1" 404 4807
Internal Server Error: /orderlineitem
Traceback (most recent call last):
  File "/root/RMS/Server/lvenv/lib/python3.8/site-packages/django/db/backends/utils.py", line 84, in _execute
    return self.cursor.execute(sql, params)
psycopg2.errors.UndefinedColumn: column Restuarant_orderlineitems.orderlineitems_id does not exist
LINE 1: SELECT "Restuarant_orderlineitems"."orderlineitems_id", "Res...
               ^


The above exception was the direct cause of the following exception:

Traceback (most recent call last):
  File "/root/RMS/Server/lvenv/lib/python3.8/site-packages/django/core/handlers/exception.py", line 47, in inner
    response = get_response(request)
  File "/root/RMS/Server/lvenv/lib/python3.8/site-packages/django/core/handlers/base.py", line 181, in _get_response
    response = wrapped_callback(request, *callback_args, **callback_kwargs)
  File "/root/RMS/Server/lvenv/lib/python3.8/site-packages/django/views/decorators/csrf.py", line 54, in wrapped_view
    return view_func(*args, **kwargs)
  File "/root/CS4227/CS4227-Application/Server/Restuarant/views.py", line 258, in orderlineitemsApi
    return JsonResponse(orderLineItemsSerializer.data, safe=False)
  File "/root/RMS/Server/lvenv/lib/python3.8/site-packages/rest_framework/serializers.py", line 745, in data
    ret = super().data
  File "/root/RMS/Server/lvenv/lib/python3.8/site-packages/rest_framework/serializers.py", line 246, in data
    self._data = self.to_representation(self.instance)
  File "/root/RMS/Server/lvenv/lib/python3.8/site-packages/rest_framework/serializers.py", line 663, in to_representation
    return [
  File "/root/RMS/Server/lvenv/lib/python3.8/site-packages/django/db/models/query.py", line 280, in __iter__
    self._fetch_all()
  File "/root/RMS/Server/lvenv/lib/python3.8/site-packages/django/db/models/query.py", line 1324, in _fetch_all
    self._result_cache = list(self._iterable_class(self))
  File "/root/RMS/Server/lvenv/lib/python3.8/site-packages/django/db/models/query.py", line 51, in __iter__
    results = compiler.execute_sql(chunked_fetch=self.chunked_fetch, chunk_size=self.chunk_size)
  File "/root/RMS/Server/lvenv/lib/python3.8/site-packages/django/db/models/sql/compiler.py", line 1175, in execute_sql
    cursor.execute(sql, params)
  File "/root/RMS/Server/lvenv/lib/python3.8/site-packages/django/db/backends/utils.py", line 98, in execute
    return super().execute(sql, params)
  File "/root/RMS/Server/lvenv/lib/python3.8/site-packages/django/db/backends/utils.py", line 66, in execute
    return self._execute_with_wrappers(sql, params, many=False, executor=self._execute)
  File "/root/RMS/Server/lvenv/lib/python3.8/site-packages/django/db/backends/utils.py", line 75, in _execute_with_wrappers
    return executor(sql, params, many, context)
  File "/root/RMS/Server/lvenv/lib/python3.8/site-packages/django/db/backends/utils.py", line 84, in _execute
    return self.cursor.execute(sql, params)
  File "/root/RMS/Server/lvenv/lib/python3.8/site-packages/django/db/utils.py", line 90, in __exit__
    raise dj_exc_value.with_traceback(traceback) from exc_value
  File "/root/RMS/Server/lvenv/lib/python3.8/site-packages/django/db/backends/utils.py", line 84, in _execute
    return self.cursor.execute(sql, params)
django.db.utils.ProgrammingError: column Restuarant_orderlineitems.orderlineitems_id does not exist
LINE 1: SELECT "Restuarant_orderlineitems"."orderlineitems_id", "Res...
               ^

[18/Feb/2022 17:21:44] "GET /orderlineitem HTTP/1.1" 500 129616
/root/CS4227/CS4227-Application/Server/Restuarant/serializers.py changed, reloading.
Performing system checks...

System check identified no issues (0 silenced).
February 18, 2022 - 17:21:41
Django version 3.2.9, using settings 'Server.settings'
Starting development server at http://0.0.0.0:8000/
Quit the server with CONTROL-C.
Watching for file changes with StatReloader
Internal Server Error: /orderlineitem
Traceback (most recent call last):
  File "/root/RMS/Server/lvenv/lib/python3.8/site-packages/django/db/backends/utils.py", line 84, in _execute
    return self.cursor.execute(sql, params)
psycopg2.errors.UndefinedColumn: column Restuarant_orderlineitems.orderlineitems_id does not exist
LINE 1: SELECT "Restuarant_orderlineitems"."orderlineitems_id", "Res...
               ^


The above exception was the direct cause of the following exception:

Traceback (most recent call last):
  File "/root/RMS/Server/lvenv/lib/python3.8/site-packages/django/core/handlers/exception.py", line 47, in inner
    response = get_response(request)
  File "/root/RMS/Server/lvenv/lib/python3.8/site-packages/django/core/handlers/base.py", line 181, in _get_response
    response = wrapped_callback(request, *callback_args, **callback_kwargs)
  File "/root/RMS/Server/lvenv/lib/python3.8/site-packages/django/views/decorators/csrf.py", line 54, in wrapped_view
    return view_func(*args, **kwargs)
  File "/root/CS4227/CS4227-Application/Server/Restuarant/views.py", line 258, in orderlineitemsApi
    return JsonResponse(orderLineItemsSerializer.data, safe=False)
  File "/root/RMS/Server/lvenv/lib/python3.8/site-packages/rest_framework/serializers.py", line 745, in data
    ret = super().data
  File "/root/RMS/Server/lvenv/lib/python3.8/site-packages/rest_framework/serializers.py", line 246, in data
    self._data = self.to_representation(self.instance)
  File "/root/RMS/Server/lvenv/lib/python3.8/site-packages/rest_framework/serializers.py", line 663, in to_representation
    return [
  File "/root/RMS/Server/lvenv/lib/python3.8/site-packages/django/db/models/query.py", line 280, in __iter__
    self._fetch_all()
  File "/root/RMS/Server/lvenv/lib/python3.8/site-packages/django/db/models/query.py", line 1324, in _fetch_all
    self._result_cache = list(self._iterable_class(self))
  File "/root/RMS/Server/lvenv/lib/python3.8/site-packages/django/db/models/query.py", line 51, in __iter__
    results = compiler.execute_sql(chunked_fetch=self.chunked_fetch, chunk_size=self.chunk_size)
  File "/root/RMS/Server/lvenv/lib/python3.8/site-packages/django/db/models/sql/compiler.py", line 1175, in execute_sql
    cursor.execute(sql, params)
  File "/root/RMS/Server/lvenv/lib/python3.8/site-packages/django/db/backends/utils.py", line 98, in execute
    return super().execute(sql, params)
  File "/root/RMS/Server/lvenv/lib/python3.8/site-packages/django/db/backends/utils.py", line 66, in execute
    return self._execute_with_wrappers(sql, params, many=False, executor=self._execute)
  File "/root/RMS/Server/lvenv/lib/python3.8/site-packages/django/db/backends/utils.py", line 75, in _execute_with_wrappers
    return executor(sql, params, many, context)
  File "/root/RMS/Server/lvenv/lib/python3.8/site-packages/django/db/backends/utils.py", line 84, in _execute
    return self.cursor.execute(sql, params)
  File "/root/RMS/Server/lvenv/lib/python3.8/site-packages/django/db/utils.py", line 90, in __exit__
    raise dj_exc_value.with_traceback(traceback) from exc_value
  File "/root/RMS/Server/lvenv/lib/python3.8/site-packages/django/db/backends/utils.py", line 84, in _execute
    return self.cursor.execute(sql, params)
django.db.utils.ProgrammingError: column Restuarant_orderlineitems.orderlineitems_id does not exist
LINE 1: SELECT "Restuarant_orderlineitems"."orderlineitems_id", "Res...
               ^

[18/Feb/2022 17:22:18] "GET /orderlineitem HTTP/1.1" 500 129164
/root/CS4227/CS4227-Application/Server/Restuarant/models.py changed, reloading.
Performing system checks...

System check identified no issues (0 silenced).
February 18, 2022 - 17:22:16
Django version 3.2.9, using settings 'Server.settings'
Starting development server at http://0.0.0.0:8000/
Quit the server with CONTROL-C.
Watching for file changes with StatReloader
Internal Server Error: /orderlineitem
Traceback (most recent call last):
  File "/root/RMS/Server/lvenv/lib/python3.8/site-packages/django/db/backends/utils.py", line 84, in _execute
    return self.cursor.execute(sql, params)
psycopg2.errors.UndefinedColumn: column Restuarant_orderlineitems.order_id_id does not exist
LINE 1: SELECT "Restuarant_orderlineitems"."line_item", "Restuarant_...
                                                        ^
HINT:  Perhaps you meant to reference the column "Restuarant_orderlineitems.Order_id_id".


The above exception was the direct cause of the following exception:

Traceback (most recent call last):
  File "/root/RMS/Server/lvenv/lib/python3.8/site-packages/django/core/handlers/exception.py", line 47, in inner
    response = get_response(request)
  File "/root/RMS/Server/lvenv/lib/python3.8/site-packages/django/core/handlers/base.py", line 181, in _get_response
    response = wrapped_callback(request, *callback_args, **callback_kwargs)
  File "/root/RMS/Server/lvenv/lib/python3.8/site-packages/django/views/decorators/csrf.py", line 54, in wrapped_view
    return view_func(*args, **kwargs)
  File "/root/CS4227/CS4227-Application/Server/Restuarant/views.py", line 258, in orderlineitemsApi
    return JsonResponse(orderLineItemsSerializer.data, safe=False)
  File "/root/RMS/Server/lvenv/lib/python3.8/site-packages/rest_framework/serializers.py", line 745, in data
    ret = super().data
  File "/root/RMS/Server/lvenv/lib/python3.8/site-packages/rest_framework/serializers.py", line 246, in data
    self._data = self.to_representation(self.instance)
  File "/root/RMS/Server/lvenv/lib/python3.8/site-packages/rest_framework/serializers.py", line 663, in to_representation
    return [
  File "/root/RMS/Server/lvenv/lib/python3.8/site-packages/django/db/models/query.py", line 280, in __iter__
    self._fetch_all()
  File "/root/RMS/Server/lvenv/lib/python3.8/site-packages/django/db/models/query.py", line 1324, in _fetch_all
    self._result_cache = list(self._iterable_class(self))
  File "/root/RMS/Server/lvenv/lib/python3.8/site-packages/django/db/models/query.py", line 51, in __iter__
    results = compiler.execute_sql(chunked_fetch=self.chunked_fetch, chunk_size=self.chunk_size)
  File "/root/RMS/Server/lvenv/lib/python3.8/site-packages/django/db/models/sql/compiler.py", line 1175, in execute_sql
    cursor.execute(sql, params)
  File "/root/RMS/Server/lvenv/lib/python3.8/site-packages/django/db/backends/utils.py", line 98, in execute
    return super().execute(sql, params)
  File "/root/RMS/Server/lvenv/lib/python3.8/site-packages/django/db/backends/utils.py", line 66, in execute
    return self._execute_with_wrappers(sql, params, many=False, executor=self._execute)
  File "/root/RMS/Server/lvenv/lib/python3.8/site-packages/django/db/backends/utils.py", line 75, in _execute_with_wrappers
    return executor(sql, params, many, context)
  File "/root/RMS/Server/lvenv/lib/python3.8/site-packages/django/db/backends/utils.py", line 84, in _execute
    return self.cursor.execute(sql, params)
  File "/root/RMS/Server/lvenv/lib/python3.8/site-packages/django/db/utils.py", line 90, in __exit__
    raise dj_exc_value.with_traceback(traceback) from exc_value
  File "/root/RMS/Server/lvenv/lib/python3.8/site-packages/django/db/backends/utils.py", line 84, in _execute
    return self.cursor.execute(sql, params)
django.db.utils.ProgrammingError: column Restuarant_orderlineitems.order_id_id does not exist
LINE 1: SELECT "Restuarant_orderlineitems"."line_item", "Restuarant_...
                                                        ^
HINT:  Perhaps you meant to reference the column "Restuarant_orderlineitems.Order_id_id".

[18/Feb/2022 17:22:34] "GET /orderlineitem HTTP/1.1" 500 131993
Internal Server Error: /orderlineitem
Traceback (most recent call last):
  File "/root/RMS/Server/lvenv/lib/python3.8/site-packages/django/db/backends/utils.py", line 84, in _execute
    return self.cursor.execute(sql, params)
psycopg2.errors.UndefinedColumn: column Restuarant_orderlineitems.order_id_id does not exist
LINE 1: SELECT "Restuarant_orderlineitems"."line_item", "Restuarant_...
                                                        ^
HINT:  Perhaps you meant to reference the column "Restuarant_orderlineitems.Order_id_id".


The above exception was the direct cause of the following exception:

Traceback (most recent call last):
  File "/root/RMS/Server/lvenv/lib/python3.8/site-packages/django/core/handlers/exception.py", line 47, in inner
    response = get_response(request)
  File "/root/RMS/Server/lvenv/lib/python3.8/site-packages/django/core/handlers/base.py", line 181, in _get_response
    response = wrapped_callback(request, *callback_args, **callback_kwargs)
  File "/root/RMS/Server/lvenv/lib/python3.8/site-packages/django/views/decorators/csrf.py", line 54, in wrapped_view
    return view_func(*args, **kwargs)
  File "/root/CS4227/CS4227-Application/Server/Restuarant/views.py", line 258, in orderlineitemsApi
    return JsonResponse(orderLineItemsSerializer.data, safe=False)
  File "/root/RMS/Server/lvenv/lib/python3.8/site-packages/rest_framework/serializers.py", line 745, in data
    ret = super().data
  File "/root/RMS/Server/lvenv/lib/python3.8/site-packages/rest_framework/serializers.py", line 246, in data
    self._data = self.to_representation(self.instance)
  File "/root/RMS/Server/lvenv/lib/python3.8/site-packages/rest_framework/serializers.py", line 663, in to_representation
    return [
  File "/root/RMS/Server/lvenv/lib/python3.8/site-packages/django/db/models/query.py", line 280, in __iter__
    self._fetch_all()
  File "/root/RMS/Server/lvenv/lib/python3.8/site-packages/django/db/models/query.py", line 1324, in _fetch_all
    self._result_cache = list(self._iterable_class(self))
  File "/root/RMS/Server/lvenv/lib/python3.8/site-packages/django/db/models/query.py", line 51, in __iter__
    results = compiler.execute_sql(chunked_fetch=self.chunked_fetch, chunk_size=self.chunk_size)
  File "/root/RMS/Server/lvenv/lib/python3.8/site-packages/django/db/models/sql/compiler.py", line 1175, in execute_sql
    cursor.execute(sql, params)
  File "/root/RMS/Server/lvenv/lib/python3.8/site-packages/django/db/backends/utils.py", line 98, in execute
    return super().execute(sql, params)
  File "/root/RMS/Server/lvenv/lib/python3.8/site-packages/django/db/backends/utils.py", line 66, in execute
    return self._execute_with_wrappers(sql, params, many=False, executor=self._execute)
  File "/root/RMS/Server/lvenv/lib/python3.8/site-packages/django/db/backends/utils.py", line 75, in _execute_with_wrappers
    return executor(sql, params, many, context)
  File "/root/RMS/Server/lvenv/lib/python3.8/site-packages/django/db/backends/utils.py", line 84, in _execute
    return self.cursor.execute(sql, params)
  File "/root/RMS/Server/lvenv/lib/python3.8/site-packages/django/db/utils.py", line 90, in __exit__
    raise dj_exc_value.with_traceback(traceback) from exc_value
  File "/root/RMS/Server/lvenv/lib/python3.8/site-packages/django/db/backends/utils.py", line 84, in _execute
    return self.cursor.execute(sql, params)
django.db.utils.ProgrammingError: column Restuarant_orderlineitems.order_id_id does not exist
LINE 1: SELECT "Restuarant_orderlineitems"."line_item", "Restuarant_...
                                                        ^
HINT:  Perhaps you meant to reference the column "Restuarant_orderlineitems.Order_id_id".

[18/Feb/2022 17:23:10] "GET /orderlineitem HTTP/1.1" 500 131993
Internal Server Error: /orderlineitem
Traceback (most recent call last):
  File "/root/RMS/Server/lvenv/lib/python3.8/site-packages/django/db/backends/utils.py", line 84, in _execute
    return self.cursor.execute(sql, params)
psycopg2.errors.UndefinedColumn: column Restuarant_orderlineitems.order_id_id does not exist
LINE 1: SELECT "Restuarant_orderlineitems"."line_item", "Restuarant_...
                                                        ^
HINT:  Perhaps you meant to reference the column "Restuarant_orderlineitems.Order_id_id".


The above exception was the direct cause of the following exception:

Traceback (most recent call last):
  File "/root/RMS/Server/lvenv/lib/python3.8/site-packages/django/core/handlers/exception.py", line 47, in inner
    response = get_response(request)
  File "/root/RMS/Server/lvenv/lib/python3.8/site-packages/django/core/handlers/base.py", line 181, in _get_response
    response = wrapped_callback(request, *callback_args, **callback_kwargs)
  File "/root/RMS/Server/lvenv/lib/python3.8/site-packages/django/views/decorators/csrf.py", line 54, in wrapped_view
    return view_func(*args, **kwargs)
  File "/root/CS4227/CS4227-Application/Server/Restuarant/views.py", line 258, in orderlineitemsApi
    return JsonResponse(orderLineItemsSerializer.data, safe=False)
  File "/root/RMS/Server/lvenv/lib/python3.8/site-packages/rest_framework/serializers.py", line 745, in data
    ret = super().data
  File "/root/RMS/Server/lvenv/lib/python3.8/site-packages/rest_framework/serializers.py", line 246, in data
    self._data = self.to_representation(self.instance)
  File "/root/RMS/Server/lvenv/lib/python3.8/site-packages/rest_framework/serializers.py", line 663, in to_representation
    return [
  File "/root/RMS/Server/lvenv/lib/python3.8/site-packages/django/db/models/query.py", line 280, in __iter__
    self._fetch_all()
  File "/root/RMS/Server/lvenv/lib/python3.8/site-packages/django/db/models/query.py", line 1324, in _fetch_all
    self._result_cache = list(self._iterable_class(self))
  File "/root/RMS/Server/lvenv/lib/python3.8/site-packages/django/db/models/query.py", line 51, in __iter__
    results = compiler.execute_sql(chunked_fetch=self.chunked_fetch, chunk_size=self.chunk_size)
  File "/root/RMS/Server/lvenv/lib/python3.8/site-packages/django/db/models/sql/compiler.py", line 1175, in execute_sql
    cursor.execute(sql, params)
  File "/root/RMS/Server/lvenv/lib/python3.8/site-packages/django/db/backends/utils.py", line 98, in execute
    return super().execute(sql, params)
  File "/root/RMS/Server/lvenv/lib/python3.8/site-packages/django/db/backends/utils.py", line 66, in execute
    return self._execute_with_wrappers(sql, params, many=False, executor=self._execute)
  File "/root/RMS/Server/lvenv/lib/python3.8/site-packages/django/db/backends/utils.py", line 75, in _execute_with_wrappers
    return executor(sql, params, many, context)
  File "/root/RMS/Server/lvenv/lib/python3.8/site-packages/django/db/backends/utils.py", line 84, in _execute
    return self.cursor.execute(sql, params)
  File "/root/RMS/Server/lvenv/lib/python3.8/site-packages/django/db/utils.py", line 90, in __exit__
    raise dj_exc_value.with_traceback(traceback) from exc_value
  File "/root/RMS/Server/lvenv/lib/python3.8/site-packages/django/db/backends/utils.py", line 84, in _execute
    return self.cursor.execute(sql, params)
django.db.utils.ProgrammingError: column Restuarant_orderlineitems.order_id_id does not exist
LINE 1: SELECT "Restuarant_orderlineitems"."line_item", "Restuarant_...
                                                        ^
HINT:  Perhaps you meant to reference the column "Restuarant_orderlineitems.Order_id_id".

[18/Feb/2022 17:23:47] "GET /orderlineitem HTTP/1.1" 500 131993
Internal Server Error: /orderlineitem
Traceback (most recent call last):
  File "/root/RMS/Server/lvenv/lib/python3.8/site-packages/django/db/backends/utils.py", line 84, in _execute
    return self.cursor.execute(sql, params)
psycopg2.errors.UndefinedColumn: column Restuarant_orderlineitems.order_id_id does not exist
LINE 1: SELECT "Restuarant_orderlineitems"."line_item", "Restuarant_...
                                                        ^
HINT:  Perhaps you meant to reference the column "Restuarant_orderlineitems.Order_id_id".


The above exception was the direct cause of the following exception:

Traceback (most recent call last):
  File "/root/RMS/Server/lvenv/lib/python3.8/site-packages/django/core/handlers/exception.py", line 47, in inner
    response = get_response(request)
  File "/root/RMS/Server/lvenv/lib/python3.8/site-packages/django/core/handlers/base.py", line 181, in _get_response
    response = wrapped_callback(request, *callback_args, **callback_kwargs)
  File "/root/RMS/Server/lvenv/lib/python3.8/site-packages/django/views/decorators/csrf.py", line 54, in wrapped_view
    return view_func(*args, **kwargs)
  File "/root/CS4227/CS4227-Application/Server/Restuarant/views.py", line 258, in orderlineitemsApi
    return JsonResponse(orderLineItemsSerializer.data, safe=False)
  File "/root/RMS/Server/lvenv/lib/python3.8/site-packages/rest_framework/serializers.py", line 745, in data
    ret = super().data
  File "/root/RMS/Server/lvenv/lib/python3.8/site-packages/rest_framework/serializers.py", line 246, in data
    self._data = self.to_representation(self.instance)
  File "/root/RMS/Server/lvenv/lib/python3.8/site-packages/rest_framework/serializers.py", line 663, in to_representation
    return [
  File "/root/RMS/Server/lvenv/lib/python3.8/site-packages/django/db/models/query.py", line 280, in __iter__
    self._fetch_all()
  File "/root/RMS/Server/lvenv/lib/python3.8/site-packages/django/db/models/query.py", line 1324, in _fetch_all
    self._result_cache = list(self._iterable_class(self))
  File "/root/RMS/Server/lvenv/lib/python3.8/site-packages/django/db/models/query.py", line 51, in __iter__
    results = compiler.execute_sql(chunked_fetch=self.chunked_fetch, chunk_size=self.chunk_size)
  File "/root/RMS/Server/lvenv/lib/python3.8/site-packages/django/db/models/sql/compiler.py", line 1175, in execute_sql
    cursor.execute(sql, params)
  File "/root/RMS/Server/lvenv/lib/python3.8/site-packages/django/db/backends/utils.py", line 98, in execute
    return super().execute(sql, params)
  File "/root/RMS/Server/lvenv/lib/python3.8/site-packages/django/db/backends/utils.py", line 66, in execute
    return self._execute_with_wrappers(sql, params, many=False, executor=self._execute)
  File "/root/RMS/Server/lvenv/lib/python3.8/site-packages/django/db/backends/utils.py", line 75, in _execute_with_wrappers
    return executor(sql, params, many, context)
  File "/root/RMS/Server/lvenv/lib/python3.8/site-packages/django/db/backends/utils.py", line 84, in _execute
    return self.cursor.execute(sql, params)
  File "/root/RMS/Server/lvenv/lib/python3.8/site-packages/django/db/utils.py", line 90, in __exit__
    raise dj_exc_value.with_traceback(traceback) from exc_value
  File "/root/RMS/Server/lvenv/lib/python3.8/site-packages/django/db/backends/utils.py", line 84, in _execute
    return self.cursor.execute(sql, params)
django.db.utils.ProgrammingError: column Restuarant_orderlineitems.order_id_id does not exist
LINE 1: SELECT "Restuarant_orderlineitems"."line_item", "Restuarant_...
                                                        ^
HINT:  Perhaps you meant to reference the column "Restuarant_orderlineitems.Order_id_id".

[18/Feb/2022 17:24:27] "GET /orderlineitem HTTP/1.1" 500 131993
Watching for file changes with StatReloader
